2019-08-03 00:13:51,002 ERROR: Exception on /explore [GET] [in %(pathname)s:1891]
Traceback (most recent call last):
  File "/Users/Daigo/.pyenv/versions/3.6.5/envs/flask_tutorial/lib/python3.6/site-packages/sqlalchemy/sql/elements.py", line 716, in __getattr__
    return getattr(self.comparator, key)
AttributeError: 'Comparator' object has no attribute 'all'

During handling of the above exception, another exception occurred:

Traceback (most recent call last):
  File "/Users/Daigo/.pyenv/versions/3.6.5/envs/flask_tutorial/lib/python3.6/site-packages/flask/app.py", line 2446, in wsgi_app
    response = self.full_dispatch_request()
  File "/Users/Daigo/.pyenv/versions/3.6.5/envs/flask_tutorial/lib/python3.6/site-packages/flask/app.py", line 1951, in full_dispatch_request
    rv = self.handle_user_exception(e)
  File "/Users/Daigo/.pyenv/versions/3.6.5/envs/flask_tutorial/lib/python3.6/site-packages/flask/app.py", line 1820, in handle_user_exception
    reraise(exc_type, exc_value, tb)
  File "/Users/Daigo/.pyenv/versions/3.6.5/envs/flask_tutorial/lib/python3.6/site-packages/flask/_compat.py", line 39, in reraise
    raise value
  File "/Users/Daigo/.pyenv/versions/3.6.5/envs/flask_tutorial/lib/python3.6/site-packages/flask/app.py", line 1949, in full_dispatch_request
    rv = self.dispatch_request()
  File "/Users/Daigo/.pyenv/versions/3.6.5/envs/flask_tutorial/lib/python3.6/site-packages/flask/app.py", line 1935, in dispatch_request
    return self.view_functions[rule.endpoint](**req.view_args)
  File "/Users/Daigo/.pyenv/versions/3.6.5/envs/flask_tutorial/lib/python3.6/site-packages/flask_login/utils.py", line 261, in decorated_view
    return func(*args, **kwargs)
  File "/Users/Daigo/git/flask_mega_tutorial/microblog/app/routes.py", line 136, in explore
    posts = Post.query.order_by(Post.timestamp.desc().all())
  File "/Users/Daigo/.pyenv/versions/3.6.5/envs/flask_tutorial/lib/python3.6/site-packages/sqlalchemy/sql/elements.py", line 720, in __getattr__
    % (type(self).__name__, type(self.comparator).__name__, key)
AttributeError: Neither 'UnaryExpression' object nor 'Comparator' object has an attribute 'all'
2019-08-03 00:28:03,167 INFO: Microblog startup [in %(pathname)s:48]
2019-08-03 00:50:14,489 INFO: Microblog startup [in %(pathname)s:48]
2019-08-03 01:03:47,623 INFO: Microblog startup [in %(pathname)s:48]
2019-08-03 01:04:06,662 ERROR: Exception on /index [POST] [in %(pathname)s:1891]
Traceback (most recent call last):
  File "/Users/Daigo/.pyenv/versions/3.6.5/envs/flask_tutorial/lib/python3.6/site-packages/flask/app.py", line 2446, in wsgi_app
    response = self.full_dispatch_request()
  File "/Users/Daigo/.pyenv/versions/3.6.5/envs/flask_tutorial/lib/python3.6/site-packages/flask/app.py", line 1951, in full_dispatch_request
    rv = self.handle_user_exception(e)
  File "/Users/Daigo/.pyenv/versions/3.6.5/envs/flask_tutorial/lib/python3.6/site-packages/flask/app.py", line 1820, in handle_user_exception
    reraise(exc_type, exc_value, tb)
  File "/Users/Daigo/.pyenv/versions/3.6.5/envs/flask_tutorial/lib/python3.6/site-packages/flask/_compat.py", line 39, in reraise
    raise value
  File "/Users/Daigo/.pyenv/versions/3.6.5/envs/flask_tutorial/lib/python3.6/site-packages/flask/app.py", line 1949, in full_dispatch_request
    rv = self.dispatch_request()
  File "/Users/Daigo/.pyenv/versions/3.6.5/envs/flask_tutorial/lib/python3.6/site-packages/flask/app.py", line 1935, in dispatch_request
    return self.view_functions[rule.endpoint](**req.view_args)
  File "/Users/Daigo/.pyenv/versions/3.6.5/envs/flask_tutorial/lib/python3.6/site-packages/flask_login/utils.py", line 261, in decorated_view
    return func(*args, **kwargs)
  File "/Users/Daigo/git/flask_mega_tutorial/microblog/app/routes.py", line 23, in index
    post = Post(body=form.post.data, author=correct_user)
NameError: name 'correct_user' is not defined
2019-08-03 01:05:32,777 INFO: Microblog startup [in %(pathname)s:48]
2019-08-03 01:10:59,166 INFO: Microblog startup [in %(pathname)s:48]
